{"stats": {"errors": 2, "failures": 0, "passes": 0, "skipped": 0, "encoding": "UTF-8", "total": 2}, "results": [{"classname": "index_test:PrivateKeyTest", "name": "test_sign", "time": 0.2575836181640625, "type": "error", "errtype": "builtins.AttributeError", "message": "'str' object has no attribute '__cause__'", "tb": "Traceback (most recent call last):\n  File \"/opt/conda/lib/python3.6/site-packages/nose/case.py\", line 133, in run\n    self.runTest(result)\n  File \"/opt/conda/lib/python3.6/site-packages/nose/case.py\", line 151, in runTest\n    test(result)\n  File \"/opt/conda/lib/python3.6/unittest/case.py\", line 653, in __call__\n    return self.run(*args, **kwds)\n  File \"/opt/conda/lib/python3.6/unittest/case.py\", line 613, in run\n    self._feedErrorsToResult(result, outcome.errors)\n  File \"/opt/conda/lib/python3.6/unittest/case.py\", line 543, in _feedErrorsToResult\n    result.addError(test, exc_info)\n  File \"/opt/conda/lib/python3.6/site-packages/nose/proxy.py\", line 131, in addError\n    plugins.addError(self.test, err)\n  File \"/opt/conda/lib/python3.6/site-packages/nose/plugins/manager.py\", line 99, in __call__\n    return self.call(*arg, **kw)\n  File \"/opt/conda/lib/python3.6/site-packages/nose/plugins/manager.py\", line 167, in simple\n    result = meth(*arg, **kw)\n  File \"/opt/conda/lib/python3.6/site-packages/nose_json/plugin.py\", line 87, in addError\n    tb = ''.join(traceback.format_exception(*err))\n  File \"/opt/conda/lib/python3.6/traceback.py\", line 117, in format_exception\n    type(value), value, tb, limit=limit).format(chain=chain))\n  File \"/opt/conda/lib/python3.6/traceback.py\", line 465, in __init__\n    if (exc_value and exc_value.__cause__ is not None\nAttributeError: 'str' object has no attribute '__cause__'\n"}]}